<?xml version="1.0" encoding="utf-8"?>
<robot name="rsc">

  <!-- Define materials -->
<material name="blue">
  <color rgba="0 0 0.8 1"/>
</material>

<material name="white">
  <color rgba="0.9 0.9 0.9 1"/>
</material>

<material name="black">
  <color rgba="0 0 0 1"/>
</material>

<material name="red">
  <color rgba="1 0 0 1"/>
</material>

<material name="yellow">
  <color rgba="1 1 0 1"/>
</material>

<material name="green">
  <color rgba="0 1 0 1"/>
</material>

<material name="orange">
  <color rgba="1 0.65 0 1"/>
</material>

<material name="purple">
  <color rgba="0.5 0 0.5 1"/>
</material>

<material name="gray">
  <color rgba="0.5 0.5 0.5 1"/>
</material>

<material name="cyan">
  <color rgba="0 1 1 1"/>
</material>

<material name="pink">
  <color rgba="1 0.75 0.8 1"/>
</material>

<material name="joy">
  <texture filename="package://my_robot_sim/textures/joy.png"/>
</material>

<material name="anger">
  <texture filename="package://my_robot_sim/textures/anger.png"/>
</material>

<material name="pride">
  <texture filename="package://my_robot_sim/textures/pride.png"/>
</material>

<material name="surprise">
  <texture filename="package://my_robot_sim/textures/surprise.png"/>
</material>

<material name="caring">
  <texture filename="package://my_robot_sim/textures/caring.png"/>
</material>

<material name="fun">
  <texture filename="package://my_robot_sim/textures/fun.png"/>
</material>

  <link name="base">
  <visual>
    <origin xyz="-0.55 0.6 0.09" rpy="1.5708 0 0"/>
    <geometry>
      <mesh filename="package://my_robot_sim/meshes/base.STL" scale="0.01 0.01 0.01" />
    </geometry>
    <material name="blue"/>
  </visual>
  <collision>
    <geometry>
      <mesh filename="package://my_robot_sim/meshes/base.STL" scale="0.01 0.01 0.01" />
    </geometry>
  </collision>
</link>
  <!-- Base Link -->
  <link name="base_link">
    <visual>
      <origin xyz="-0.6 0.44 0.4" rpy="1.5708 0 0"/>
      <geometry>
        <mesh filename="package://my_robot_sim/meshes/body2.STL" scale="0.01 0.01 0.01" />
      </geometry>
      <material name="blue"/>
    </visual>
    <collision>
      <geometry>
        <mesh filename="package://my_robot_sim/meshes/body2.STL" scale="0.01 0.01 0.01" />
      </geometry>
    </collision>
  </link>
  
  <joint name="base_to_body" type="revolute">
      <parent link="base" />
      <child link="base_link" />
      <origin xyz="0 0 0" rpy="0 0 0" />
      <axis xyz="0 0 1"/> 
      <limit effort="100" velocity="1.0" lower="-1.57" upper="1.57"/>
  </joint>
  <!-- Arm 1 Link -->
  <link name="arm_1">
    <visual>
      <origin xyz="-0.55 -0.19 -0.55" rpy="-1.5708 3.14 0"/> <!-- Define the visual origin of arm_1 -->
      <geometry>
        <mesh filename="package://my_robot_sim/meshes/rsc_flipperv8.STL" scale="0.01 0.01 0.01"/>
      </geometry>
      <material name="white"/>
    </visual>
    <collision>
      <geometry>
        <mesh filename="package://my_robot_sim/meshes/rsc_flipperv8.STL" scale="0.01 0.01 0.01"/>
      </geometry>
    </collision>
  </link>

  <!-- Joint for Arm 1 Rotation Around X-Axis Center -->
  <joint name="arm1_to_pivot" type="continuous">
    <parent link="base_link"/>
    <child link="arm_1"/>
    <origin xyz="0 0.05 0.9" rpy="0 0 0"/> <!-- Center the rotation around arm_1’s origin -->
    <axis xyz="1 0 0"/> <!-- Set rotation around x-axis -->
  </joint>





  <!-- Arm 2 Link -->
  <link name="arm_2">
    <visual>
    <origin xyz="+0.55 0.19 -0.55" rpy="1.5708 0 0"/>
      <geometry>
        <mesh filename="package://my_robot_sim/meshes/rsc_flipperv8.STL" scale="0.01 0.01 0.01"/>
      </geometry>
      <material name="white"/>
    </visual>
    <collision>
      <geometry>
        <mesh filename="package://my_robot_sim/meshes/rsc_flipperv8.STL" scale="0.01 0.01 0.01"/>
      </geometry>
    </collision>
  </link>

  <!-- Joint for Arm 1 Rotation Around X-Axis Center -->
  <joint name="arm2_to_pivot" type="continuous">
    <parent link="base_link"/>
    <child link="arm_2"/>
    <origin xyz="0 0.05 0.9" rpy="0 0 0"/> <!-- Center the rotation around arm_1’s origin -->
    <axis xyz="1 0 0"/> <!-- Set rotation around x-axis -->
  </joint>



  <link name="cornice">
    <visual>
      <origin xyz="-0.458 -0.20 0.42" rpy="1.39 0 0"/>
      <geometry>
        <mesh filename="package://my_robot_sim/meshes/cornice.STL" scale="0.01 0.01 0.01" />
      </geometry>
      <material name="white"/>
    </visual>
    <collision>
      <geometry>
        <mesh filename="package://my_robot_sim/meshes/cornice.STL" scale="0.01 0.01 0.01" />
      </geometry>
    </collision>
  </link>
  
  <joint name="cornice_to_body" type="fixed">
     <parent link="base_link" />
     <child link="cornice" />
     <origin xyz="0 0 0" rpy="0 0 0" />
</joint>


  <link name="screen">
    <visual>
      <origin xyz="-0.377 -0.25 0.5295" rpy="1.39 0 0"/>
      <geometry>
        <mesh filename="package://my_robot_sim/meshes/screen.STL" scale="0.01 0.01 0.01" />
      </geometry>
      <material name="black"/>
    </visual>
    <collision>
      <geometry>
        <mesh filename="package://my_robot_sim/meshes/screen.STL" scale="0.01 0.01 0.01" />
      </geometry>
    </collision>
  </link>
  
  <joint name="screen_to_body" type="fixed">
     <parent link="base_link" />
     <child link="screen" />
     <origin xyz="0 0 0" rpy="0 0 0" />
</joint>

<link name="image">
    <visual>
      <origin xyz="0 -0.45 0.7" rpy="1.5708 -1.5708 0"/>
      <geometry>
        <box size="0.4 0.58 0.001"/>
      </geometry>
      <material name="pride"/>
    </visual>
  </link>
  
  <joint name="image_to_body" type="fixed">
     <parent link="base_link" />
     <child link="image" />
     <origin xyz="0 0 0" rpy="-0.16 0 0" />
</joint>

  <link name="piattello">
    <visual>
      <origin xyz="-0.543 0.44 0.96" rpy="1.5708 0 0"/>
      <geometry>
        <mesh filename="package://my_robot_sim/meshes/piattello_button.STL" scale="0.01 0.01 0.01" />
      </geometry>
      <material name="white"/>
    </visual>
    <collision>
      <geometry>
        <mesh filename="package://my_robot_sim/meshes/piattello_button.STL" scale="0.01 0.01 0.01" />
      </geometry>
    </collision>
  </link>
  
  <joint name="piattello_to_body" type="fixed">
     <parent link="base_link" />
     <child link="piattello" />
     <origin xyz="0 0 0" rpy="0 0 0" />
</joint>

  <link name="button">
    <visual>
      <origin xyz="-0.3 0.4 0.78" rpy="1.5708 0 0"/>
      <geometry>
        <mesh filename="package://my_robot_sim/meshes/button.STL" scale="0.01 0.01 0.01" />
      </geometry>
      <material name="green"/>
    </visual>
    <collision>
      <geometry>
        <mesh filename="package://my_robot_sim/meshes/button.STL" scale="0.01 0.01 0.01" />
      </geometry>
    </collision>
  </link>
  
  <joint name="button_to_body" type="fixed">
     <parent link="base_link" />
     <child link="button" />
     <origin xyz="0 0 0" rpy="0 0 0" />
</joint>

  <link name="back">
    <visual>
      <origin xyz="-0.455 0.435 0.415" rpy="1.5708 0 0"/>
      <geometry>
        <mesh filename="package://my_robot_sim/meshes/back.STL" scale="0.01 0.01 0.01" />
      </geometry>
      <material name="white"/>
    </visual>
    <collision>
      <geometry>
        <mesh filename="package://my_robot_sim/meshes/back.STL" scale="0.01 0.01 0.01" />
      </geometry>
    </collision>
  </link>
  
  <joint name="back_to_body" type="fixed">
     <parent link="base_link" />
     <child link="back" />
     <origin xyz="0 0 0" rpy="0 0 0" />
</joint>







</robot>
